Workbook

Sheet INGRESO
A2: DATOS DE NEGOCIACION
A3: Negociación con PAYBACK | B3: NO
A4: Tipo de Contrato | B4: NUEVO
A5: Número de Cuenta (En caso de contrato adicional)
A6: Nombre de La Empresa / Titular | B6: Ismael Jahir Cruz Topanda
A7: RUC / CI | B7: 1725057648
A8: Fecha de nacimiento (solo cliente CI) | B8: 22/01/2003
A9: Identificación Rep Legal: (solo Juridico)
A10: Representante Legal (solo Juridico)
A11: Fecha de Vcto Nombramiento (DD/MM/AÑO)
A12: REFERENCIAS DOMICILIARIAS
A13: Ciudad: | B13: Quito
A14: Provincia | B14: Pichincha
A15: Cod de Area
A16: Telefono
A17: Numero celular | B17: Línea Nueva
A18: Correo Electronico facturacion | B18: cruz.t.isma13@gamail.com
A19: Dirección | B19: Cliente solicita retirar hoy mismo su chip en la agencia, centro comercial aeropuerto.
A20: Forma de Pago
A21: BANCOS (Ingresar Nombre De La Institución) | B21: Banco del Pichincha
A22: Tipo de cuenta | B22: AHORROS
A23: No de cuenta | B23: 2205610195
A24: Ced/Ruc dueño de cta
A25: Nombre del dueño de cuenta
A26: TARJETA DE CREDITO (Emisor De La T/C)
A27: No de Tarjeta Electronica
A28: Fecha de caducidad (DD/MM/AÑO)
A29: Cod de Seguridad
A30: Tipo de identificacion
A31: Ced/Ruc dueño de cta
A32: Nombre del dueño de cuenta
A33: Lugar de entrega de Chips
A34: Ciudad:
A35: Direccion de entrega
... A37: GESTORES *888/*611
A38: NOMBRE | C38: CI | D38: CELULAR | E38: CORREO
A39: Ismael Jahir Cruz Topanda | C39: 1725057648 | D39: Línea Nueva | E39: cruz.t.isma13@gamail.com
A43: Usuario | B43: Números a Portarse | C43: Tipo de transaccion | D43: Tarifa | E43: BP (Vigente En Guía Comercial) | F43: Equipo | G43: Financiamiento | H43: Feature | I43: CODIGO FEATURE (Vigente En Guía Comercial)
A44: Ismael Jahir Cruz Topanda | C44: LINEA NUEVA | D44: 16 | E44: 100151950

Sheet SP JURIDICA
B1: FORMATO DE SOLICITUD DE PORTABILIDAD DE NÚMEROS TELEFÓNICOS MÓVILES
B3: NÚMERO: | I3: FECHA: | T3: HORA:
B5: DATOS DEL ABONADO:
B6: PERSONA NATURAL | M6: PERSONA JURÍDICA | V6: X
B7: OTROS (Organismos públicos, asociaciones, gremios)
B8: NOMBRE DEL ABONADO/CLIENTE/REPRESENTANTE LEGAL: | K8: =INGRESO!B10 -> 0
B9: RAZON SOCIAL: | E9: =INGRESO!B6 -> Ismael Jahir Cruz Topanda
B13: MODALIDAD DE CONTRATACIÓN ACTUAL:
B15: PREPAGO | H15: POSPAGO | M15: X
B18: DATOS DEL PROVEEDOR DEL SERVICIO MÓVIL AVANZADO:
B19: PRESTADOR DONANTE: | E19: MOVISTAR
B20: PRESTADOR RECEPTOR: | E20: CLARO
B21: NÚMERO IDENTIFICADOR DEL PRESTADOR DONANTE (NIP):
B23: NÚMEROS A SER PORTADOS:
C24: 1 | D24: =INGRESO!#REF! -> #REF! | H24: 6 | O24: 11 | U24: 16
C25: 2 | D25: =INGRESO!B44 -> 0 | H25: 7 | O25: 12 | U25: 17
C26: 3 | H26: 8 | O26: 13 | U26: 18
C27: 4 | H27: 9 | O27: 14 | U27: 19
C28: 5 | H28: 10 | O28: 15 | U28: 20
B30: CANTIDAD DE NÚMEROS A SER PORTADOS: | G30: =(COUNT(D24:F28))+COUNT(I24:N28)+COUNT(P24:S28)+COUNT(V24:Y28) -> 1
B31: NÚMERO DE DOCUMENTOS ANEXOS: | G31: 1
B33: NOTAS:
B34: 1. El Abonado/cliente acepta que con la firma de la presente Solicitud de Portabilidad, manifiesta su consentimiento de terminar la relación contractual con el Prestador Donante, únicamente de los servicios de telecomunicaciones cuya prestación requiere de los números telefónicos a ser portados, a partir de la fecha efectiva en que se realice la portabilidad de los mismos. 2. El abonado/cliente en modalidad pospago, podrá portar su(s) número(s) telefónico(s), únicamente si ha dado cumplimitos a todas las obligaciones que haya contraído por la relación contractual con el Prestador Donante respecto de dicho(s) número(s), esto es, deberá previamente cancelar de forma obligatoria todos los valores que adeude por factura(s) generada(s) por el Prestador Donante, considerando todos los valores por concepto de la prestación del servicio móvil avanzado y/o los valores de financiamiento de equipo(s) terminal(es) adquirido(s), de dicho(s) número(s) telefónico(s), de conformidad a las obligaciones contraídas, al momento de presentar las solicitudes de portabilidad. 3. El Abonado/cliente reconoce que la Portabilidad del (los) número(s) solicitada está sujeta al cumplimiento de todos los requisitos establecidos en la norma técnica de portabilidad móvil. 4. El firmante declara que los datos consignados en la presente solicitud y, en su caso, los documentos que la acompañan son verdaderos.
B42: 5. Cuando una solicitud de portabilidad es rechazada, por causas imputables al abonado/cliente establecidas en las Especificaciones Técnicas y Operativas de la Norma Técnica de Portabilidad Móvil, los costos y gastos derivados de su tramitación serán asumidos por éste, conforme a las políticas comerciales del prestador del servicio móvil avanzado o móvil avanzado a través de operador móvil virtual. El valor para cubrir dichos costos y gastos será como máximo el valor de una transación de portabilidad convenido entre el prestador del servicio móvil avanzado o móvil avanzado a través de operador móvil virtual y el ASCP. 6. Causas de rechazo de una solicitud de portabilidad: Prepago: a)El solicitante de la portabilidad no sea el abonado/cliente titular del o los números a ser portados. b) La solicitud de portabilidad se presentó como prepago y se encuentra suscrito bajo el esquema pospago, o viceversa. c) El o los números a ser portados se encuentren al momento de la solicitud de portabilidad en estado retirado, cancelado o dado de baja en el Prestador Donante. d) Se considera motivo de rechazo la presencia de corrección en la solicitud del Número a ser portado y cantidad de números a ser portados; así como enmendaduras y correcciones en el documento de solicitud que no permitan la legibilidad de datos. e) No se acepatrá solicitudes de portabilidad de menores de edad. f) Será motivo de rechazo que el o los números a ser portados se encuentren suspendidos por mal uso de los números de emergencia. g) No se aceptarán solicitudes de portabilidad cuando la copia o foto del documento de identidad: Cédula, pasaporte o ficha de identidad con información o datos proporcionados por el Registro Civil, no contenga la firma o sea ilegible. Pospago: Además de las anteriores se consideran las siguientes causales: a) El solicitante de la portabilidad no sea el abonado/cliente titular del o los números a ser portados. B) Cuando el abonado/cliente en modalidad pospago adeude valores del o los números a ser portados en factura(s) generada(s) por el Prestador Donante, en la(s) cual(es) conste(n) el concepto de la prestación del servicio móvil avanzado y/o mantenga valores pendientes de financiamiento de equipo(s) terminal(es) adquirido(s), de conformidad a las obligaciones contraídas, al momento de la revisión de la solicitud de portabiliad realizada por el Prestador Donante. Éste requisito se verificará únicamente respecto de la(s) línea(s) o número(s) que se va(n) a portar. 7. A partir de la tercera portación efectiva por línea telefónica en un mismo año calendario, el Prestador Receptor podrá cobrar al abonado/cliente como máximo el valor de una transacción de portabilidad convenido entre el prestador del servicio móvil avanzado o móvil avanzado a través de operador móvil virtual y el ASCP, el mismo que se incluye en los contratos suscritos entre el ASCP y los prestadores del servicio móvil avanzado o móvil avanzado a través de operador 8. El cobro por el proceso de portabilidad, cuando sea aplicable es para cada número a portar. 9. Desistimiento de la solicitud de portabilidad por parte abonado/cliente.- Acto mediante el cual el abonado/cliente titular de un número, habiendo solicitado la portabilidad, decide finalmente dejar sin efecto dicha solicitud. La solicitud de desistimiento deberá ser presentada, ante el Prestador Receptor, hasta las 16:00 del primer día hábil contado a partir del ingreso de la solicitud de portabilidad.
B61: En función de lo anterior, el abonado declara que ha revisado el contenido de la información descrita en esta solicitud, y como tal, acepta los términos y condiciones expuestos en ella:
B66: =K8 -> 0
B67: NOMBRE DEL SUSCRIPTOR/REPRESENTANTE LEGAL | N67: FIRMA

Sheet SP NATURAL
B1: FORMATO DE SOLICITUD DE PORTABILIDAD DE NÚMEROS TELEFÓNICOS MÓVILES
B3: NÚMERO: | I3: FECHA: | T3: HORA:
B5: DATOS DEL ABONADO:
B6: PERSONA NATURAL | M6: PERSONA JURÍDICA | V6: X
B7: OTROS (Organismos públicos, asociaciones, gremios)
B8: NOMBRE DEL ABONADO/CLIENTE/REPRESENTANTE LEGAL: | K8: =INGRESO!B6 -> Ismael Jahir Cruz Topanda
B9: RAZON SOCIAL:
B13: MODALIDAD DE CONTRATACIÓN ACTUAL:
B15: PREPAGO | H15: POSPAGO | M15: X
B18: DATOS DEL PROVEEDOR DEL SERVICIO MÓVIL AVANZADO:
B19: PRESTADOR DONANTE: | E19: MOVISTAR
B20: PRESTADOR RECEPTOR: | E20: CLARO
B21: NÚMERO IDENTIFICADOR DEL PRESTADOR DONANTE (NIP):
B23: NÚMEROS A SER PORTADOS:
C24: 1 | D24: =INGRESO!#REF! -> #REF! | H24: 6 | I24: =INGRESO!B47 -> 0 | O24: 11 | P24: =INGRESO!B51 -> 0 | U24: 16 | V24: =INGRESO!B59 -> 0
C25: 2 | D25: =INGRESO!B44 -> 0 | H25: 7 | I25: =INGRESO!B48 -> 0 | O25: 12 | P25: =INGRESO!B52 -> 0 | U25: 17 | V25: =INGRESO!B60 -> 0
C26: 3 | D26: =INGRESO!#REF! -> #REF! | H26: 8 | I26: =INGRESO!B49 -> 0 | O26: 13 | P26: =INGRESO!B53 -> 0 | U26: 18 | V26: =INGRESO!B61 -> 0
C27: 4 | D27: =INGRESO!B45 -> 0 | H27: 9 | I27: =INGRESO!B58 -> 0 | O27: 14 | P27: =INGRESO!B54 -> 0 | U27: 19 | V27: =INGRESO!B56 -> 0
C28: 5 | D28: =INGRESO!B46 -> 0 | H28: 10 | I28: =INGRESO!B50 -> 0 | O28: 15 | P28: =INGRESO!B55 -> 0 | U28: 20 | V28: =INGRESO!B57 -> 0
B30: CANTIDAD DE NÚMEROS A SER PORTADOS: | G30: =(COUNT(D24:F28))+COUNT(I24:N28)+COUNT(P24:S28)+COUNT(V24:Y28) -> 18
B31: NÚMERO DE DOCUMENTOS ANEXOS: | G31: 1
B33: NOTAS:
B34: 1. El Abonado/cliente acepta que con la firma de la presente Solicitud de Portabilidad, manifiesta su consentimiento de terminar la relación contractual con el Prestador Donante, únicamente de los servicios de telecomunicaciones cuya prestación requiere de los números telefónicos a ser portados, a partir de la fecha efectiva en que se realice la portabilidad de los mismos. 2. El abonado/cliente en modalidad pospago, podrá portar su(s) número(s) telefónico(s), únicamente si ha dado cumplimitos a todas las obligaciones que haya contraído por la relación contractual con el Prestador Donante respecto de dicho(s) número(s), esto es, deberá previamente cancelar de forma obligatoria todos los valores que adeude por factura(s) generada(s) por el Prestador Donante, considerando todos los valores por concepto de la prestación del servicio móvil avanzado y/o los valores de financiamiento de equipo(s) terminal(es) adquirido(s), de dicho(s) número(s) telefónico(s), de conformidad a las obligaciones contraídas, al momento de presentar las solicitudes de portabilidad. 3. El Abonado/cliente reconoce que la Portabilidad del (los) número(s) solicitada está sujeta al cumplimiento de todos los requisitos establecidos en la norma técnica de portabilidad móvil. 4. El firmante declara que los datos consignados en la presente solicitud y, en su caso, los documentos que la acompañan son verdaderos.
B42: 5. Cuando una solicitud de portabilidad es rechazada, por causas imputables al abonado/cliente establecidas en las Especificaciones Técnicas y Operativas de la Norma Técnica de Portabilidad Móvil, los costos y gastos derivados de su tramitación serán asumidos por éste, conforme a las políticas comerciales del prestador del servicio móvil avanzado o móvil avanzado a través de operador móvil virtual. El valor para cubrir dichos costos y gastos será como máximo el valor de una transación de portabilidad convenido entre el prestador del servicio móvil avanzado o móvil avanzado a través de operador móvil virtual y el ASCP. 6. Causas de rechazo de una solicitud de portabilidad: Prepago: a)El solicitante de la portabilidad no sea el abonado/cliente titular del o los números a ser portados. b) La solicitud de portabilidad se presentó como prepago y se encuentra suscrito bajo el esquema pospago, o viceversa. c) El o los números a ser portados se encuentren al momento de la solicitud de portabilidad en estado retirado, cancelado o dado de baja en el Prestador Donante. d) Se considera motivo de rechazo la presencia de corrección en la solicitud del Número a ser portado y cantidad de números a ser portados; así como enmendaduras y correcciones en el documento de solicitud que no permitan la legibilidad de datos. e) No se acepatrá solicitudes de portabilidad de menores de edad. f) Será motivo de rechazo que el o los números a ser portados se encuentren suspendidos por mal uso de los números de emergencia. g) No se aceptarán solicitudes de portabilidad cuando la copia o foto del documento de identidad: Cédula, pasaporte o ficha de identidad con información o datos proporcionados por el Registro Civil, no contenga la firma o sea ilegible. Pospago: Además de las anteriores se consideran las siguientes causales: a) El solicitante de la portabilidad no sea el abonado/cliente titular del o los números a ser portados. B) Cuando el abonado/cliente en modalidad pospago adeude valores del o los números a ser portados en factura(s) generada(s) por el Prestador Donante, en la(s) cual(es) conste(n) el concepto de la prestación del servicio móvil avanzado y/o mantenga valores pendientes de financiamiento de equipo(s) terminal(es) adquirido(s), de conformidad a las obligaciones contraídas, al momento de la revisión de la solicitud de portabiliad realizada por el Prestador Donante. Éste requisito se verificará únicamente respecto de la(s) línea(s) o número(s) que se va(n) a portar. 7. A partir de la tercera portación efectiva por línea telefónica en un mismo año calendario, el Prestador Receptor podrá cobrar al abonado/cliente como máximo el valor de una transacción de portabilidad convenido entre el prestador del servicio móvil avanzado o móvil avanzado a través de operador móvil virtual y el ASCP, el mismo que se incluye en los contratos suscritos entre el ASCP y los prestadores del servicio móvil avanzado o móvil avanzado a través de operador 8. El cobro por el proceso de portabilidad, cuando sea aplicable es para cada número a portar. 9. Desistimiento de la solicitud de portabilidad por parte abonado/cliente.- Acto mediante el cual el abonado/cliente titular de un número, habiendo solicitado la portabilidad, decide finalmente dejar sin efecto dicha solicitud. La solicitud de desistimiento deberá ser presentada, ante el Prestador Receptor, hasta las 16:00 del primer día hábil contado a partir del ingreso de la solicitud de portabilidad.
B61: En función de lo anterior, el abonado declara que ha revisado el contenido de la información descrita en esta solicitud, y como tal, acepta los términos y condiciones expuestos en ella:
B66: =K8 -> Ismael Jahir Cruz Topanda
B67: NOMBRE DEL SUSCRIPTOR/REPRESENTANTE LEGAL | N67: FIRMA

Sheet GESTOR JUR
G1: Quito, | H1: =TODAY() -> 46133
B3: Señores CONSORCIO ECUATORIANO DE TELECOMUNICACIONES S.A. CONECEL Quito.- De mis consideraciones:
B5: Yo, | C5: =INGRESO!B10 -> 0 | F5: en calidad de | G5: representante legal, de la compañía
B6: =INGRESO!B6 -> Ismael Jahir Cruz Topanda | E6: , con RUC No. | F6: =INGRESO!B7 -> 1725057648 | G6: , tengo a bien indicarles que
B7: además del número telefónico | E7: 999569172 | F7: y correo electrónico | G7: gerencia.irtelc@gmail.com
B8: que me pertenece, autorizo al/los señor/es:
B10: NOMBRE | E10: CI | F10: CELULAR | G10: CORREO | H10: FAMILIA PRODUCTO*
B11: =INGRESO!A39 -> Ismael Jahir Cruz Topanda | E11: =INGRESO!C39 -> 1725057648 | F11: =INGRESO!D39 -> Línea Nueva | G11: =INGRESO!E39 -> cruz.t.isma13@gamail.com | H11: Todas
B12: =INGRESO!A40 -> 0 | E12: =INGRESO!C40 -> 0 | F12: =INGRESO!D40 -> 0 | G12: =INGRESO!E40 -> 0 | H12: Todas
B13: =INGRESO!A41 -> 0 | E13: =INGRESO!C41 -> 0 | F13: =INGRESO!D41 -> 0 | G13: =INGRESO!E41 -> 0
B14: *Familia Producto. Para aquellos administradores que requieran tener exclusividad en la administración de alguna Familia de producto, indicar dicha familia en esta columna. Representación de Familias: Analítica, Cloud, IOT, Datacenter, Internet, Datos, Voz, Servicio Móvil, Seguridad, Servicios IT y Televisión; caso contrario se debe mantener en Familia Producto “Todas”.
B15: Quien/es mediante este documento queda/n designado/s como ADMINISTRADOR/ES de la/s cuenta/s, para que en nombre y representación de mí representada, proceda a realizar las transacciones y/o gestiones por medio de correo electrónico o por medio del Asesor Empresarial y/o Ejecutivo designado para la/s cuenta/s de mí representada, conforme a los siguientes términos: Las gestiones y/o transacciones que realizarán son las siguientes: • Activación/Reactivación y desactivación de servicios. • Activación de esquemas adicionales. • Actualización de información de la cuenta. • Autoservicio. • Consulta de servicios. • Cambio de características del plan/línea. • Adendum y Renovaciones. • Recepción y Gestión de Novedades. • Solicitudes de Bloqueos/Desbloqueos. • Suspensión/Reactivación por robo. • Reporterías definidas. • Modificación Umbrales y Límites de consumo. • Gestión de solicitudes de portabilidad. Adicionalmente, declaro que se carguen en la factura inmediata siguiente, los valores adicionales y/o equipos incluidos SIMCARDS. A su vez que cualquiera de el/los contacto/s autorizado/s vía correo electrónico puedan recibir equipos ACEPTO En virtud de lo anterior, expresamente manifiesto que el requerimiento y/o aceptación conferida por el/los Administrador/es de la Cuenta vía correo electrónico, cuenta con mi aceptación y ratificación en forma expresa, con pleno conocimiento de todas las condiciones contractuales que implican los servicios contratados a CONECEL por mi representada; de esta forma, no será necesario ninguna autorización adicional y únicamente bastará el correo electrónico de el/los Administrador/es de la Cuenta registrado/s requiriendo y aceptando la gestión y/o transacción correspondiente.
B16: Los requerimientos llevan implícita la obligación de mi representada de pagar el valor correspondiente por el(los) servicio/s, hasta cubrir el costo total del (los) mismo(s) a la forma de pago acordado y plazos determinados con CONECEL. Queda estipulada la obligación que tengo de notificar a CONECEL sobre los cambios de administradores que realice vía correo electrónico, así como también remitir la correspondiente carta de autorización escrita a los nuevos ADMINISTRADORES, en caso que no lo llegase a realizar CONECEL no será responsable por los requerimientos que realice el/los administradores anteriormente autorizado/s. En virtud de lo expuesto, declaro asumir enteramente la responsabilidad por el uso que dé/n el/los Administrador/es las claves, así como también respecto de las acciones, solicitudes vía correo electrónico y/o transacciones que ejecute por medio de los canales de venta de CONECEL, para lo cual doy por ratificadas dichas gestiones y/o transacciones y me obligo a cumplirlas en su totalidad sin ningún tipo de limitación en tal sentido; incluso, en aquellos casos en los que el Contacto de la Cuenta se extralimitare en sus funciones, asumiendo personalmente las consecuencias que se puedan generar de dicha situación. Finalmente, mientras dure el contrato de prestación de servicio, autorizo a CONECEL para que me comunique las ofertas y publicidades de los productos y servicios comercializados, así como también procesa a acceder y usar información referente a consumo de mis cuentas de servicio, ya sea en forma directa o por medio de sus proveedores.
B17: Así también, | D17: =INGRESO!B6 -> Ismael Jahir Cruz Topanda | G17: declara contar con una
B18: base de legitimación para tratar los datos personales de los titulares, en el ejercicio de sus funciones para reportarlos como administradores de las cuentas de los servicios contratados con CLARO, y garantiza la veracidad de la información, para su posterior registro y uso por parte de CONECEL en la prestación de servicios postventa. Atentamente,
B19: Por CLIENTE.
E21: NOMBRE: | F21: =INGRESO!B10 -> 0
E22: CED/RUC: | F22: =E11 -> 1725057648

Sheet GESTOR NATU
F1: Quito, | G1: =TODAY() -> 46133
B3: Señores CONSORCIO ECUATORIANO DE TELECOMUNICACIONES S.A. CONECEL Quito.- De mis consideraciones:
B5: Yo, | C5: =INGRESO!B6 -> Ismael Jahir Cruz Topanda | E5: ,portador de la cédula de ciudadanía/Pasaporte No. | G5: =INGRESO!B7 -> 1725057648
B6: , autorizo al/los señor/es:
B8: NOMBRE | E8: CI | F8: CELULAR | G8: CORREO
B9: =C5 -> Ismael Jahir Cruz Topanda | E9: =INGRESO!B9 -> 0 | F9: =INGRESO!D39 -> Línea Nueva | G9: =INGRESO!E39 -> cruz.t.isma13@gamail.com
B10: =INGRESO!A40 -> 0 | E10: =INGRESO!C40 -> 0 | F10: =INGRESO!D40 -> 0 | G10: =INGRESO!E40 -> 0
B11: =INGRESO!A41 -> 0 | E11: =INGRESO!C41 -> 0 | F11: =INGRESO!D41 -> 0 | G11: =INGRESO!E41 -> 0
B12: Quien/es mediante este documento queda/n designado/s como ADMINISTRADOR/ES de mi cuenta, para que en mi nombre y representación, procedan a realizar las transacciones y/o gestiones por medio de correo electrónico o por medio del Asesor Empresarial y/o Ejecutivo designado para la cuenta cuya titularidad me pertenece, conforme a los siguientes términos: Las gestiones y/o transacciones que realizarán son las siguientes: • Activación/Reactivación y desactivación de servicios. • Activación de esquemas adicionales. • Actualización de información de la cuenta. • Autoservicio. • Consulta de servicios. • Cambio de características del plan/línea. • Adendum y Renovaciones. • Recepción y Gestión de Novedades. • Solicitudes de Bloqueos/Desbloqueos. • Suspensión/Reactivación por robo. • Reporterías definidas. • Modificación Umbrales y Límites de consumo. • Gestión de solicitudes de portabilidad. Adicionalmente, declaro que se carguen en la factura inmediata siguiente, los valores adicionales y/o equipos incluidos SIMCARDS. A su vez que cualquiera de el/los contacto/s autorizado/s vía correo electrónico puedan recibir equipos ACEPTO En virtud de lo anterior, expresamente manifiesto que el requerimiento y/o aceptación conferida por el/los Administrador/es de mi Cuenta vía correo electrónico, cuenta con mi aceptación y ratificación en forma expresa, con pleno conocimiento de todas las condiciones contractuales que implican los servicios contratados a CONECEL por mi representada; de esta forma, no será necesario ninguna autorización adicional y únicamente bastará el correo electrónico de el/los Administrador/es de mi Cuenta registrado/s requiriendo y aceptando la gestión y/o transacción correspondiente.
B13: Los requerimientos de el/los Administrador/es de mi Cuenta llevan implícita mi obligación de pagar el valor correspondiente por el(los) servicio/s, hasta cubrir el costo total del (los) mismo(s) a la forma de pago acordado y plazos determinados con CONECEL. Queda estipulada la obligación que tengo de notificar vía correo electrónico a CONECEL sobre los cambios de el/los administrador/es que realice, así como también la suscripción de la correspondiente carta de AUTORIZACION de el/los ADMINISTRADORES, en caso que no lo llegase a realizar CONECEL no será responsable por los requerimientos que realice el/los administradores anteriormente autorizado/s. En virtud de lo expuesto, declaro asumir enteramente la responsabilidad por el uso que dé/n el/los Administrador/es a las claves, así como también respecto de las acciones, solicitudes vía correo electrónico y/o transacciones que ejecute por medio de los canales de venta de Conecel, para lo cual doy por ratificadas dichas gestiones y/o transacciones y me obligo a cumplirlas en su totalidad sin ningún tipo de limitación en tal sentido; incluso, en aquellos casos en los que el/los administrador/es de mi Cuenta se extralimitare/n en sus funciones, asumiendo personalmente las consecuencias que se puedan generar de dicha situación. Finalmente, mientras dure el contrato de prestación del servicio de Conecel, autorizo a ésta última para que me comunique las ofertas y publicidades de los productos y servicios que comercialice, así como también procesa a acceder y usar información referente a consumo de mis cuentas de servicio, ya sea en forma directa o por medio de sus proveedores, con la finalidad de ofrecerme nuevas opciones de servicios. Atentamente,
B14: Por CLIENTE.
E16: NOMBRE: | F16: =B9 -> Ismael Jahir Cruz Topanda
E17: CED/RUC: | F17: =E9 -> 0
C21: CONTACTO DE LA CUENTA | F21: CONTACTO DE LA CUENTA
C23: NOMBRE: | D23: =B10 -> 0 | F23: NOMBRE: | G23: =B11 -> 0
C24: CED/RUC: | D24: =E10 -> 0 | F24: CED/RUC: | G24: =E11 -> 0

Sheet entrega recepcion
B1: Acta de entrega de SIMCARDS
B2: LINEA NUEVA Y PORTABILIDAD
B3: CLIENTE | C3: =INGRESO!B6 -> Ismael Jahir Cruz Topanda
B4: CI/RUC | C4: =INGRESO!B7 -> 1725057648
B5: FECHA ACTA | C5: =TODAY() -> 46133
B7: DETALLE
B8: ICC | C8: NÚMERO | D8: PLAN | E8: TARIFA | F8: FECHA DE ACTIVACION
B9: 895930100111477706 | C9: PENDIENTE | D9: SIN LIMITE 10 | E9: $10.00 | F9: PENDIENTE
B10: 895930100111477707 | C10: PENDIENTE | D10: SIN LIMITE 10 | E10: $10.00 | F10: PENDIENTE
B11: 895930100111477705 | C11: PENDIENTE | D11: SIN LIMITE 10 | E11: $10.00 | F11: PENDIENTE
B12: 895930100111477671 | C12: PENDIENTE | D12: SIN LIMITE 10 | E12: $10.00 | F12: PENDIENTE
B13: 895930100111477678 | C13: PENDIENTE | D13: SIN LIMITE 10 | E13: $10.00 | F13: PENDIENTE
B14: 895930100111477714 | C14: PENDIENTE | D14: SIN LIMITE 10 | E14: $10.00 | F14: PENDIENTE
B15: 895930100111445438 | D15: SIN LIMITE 15 | E15: $15.00 | F15: PENDIENTE
B17: • Por medio del presente Acta se deja constancia de la recepción de todos los simcards detallados, la custodia y total responsabilidad sobre los mismos de la persona que firma este documento.
B18: • Para realizar consultas, solicitudes o reclamos lo puede efectuar por medio de su asesor (a) comercial.
B21: GABRIEL GUZMAN
E22: FIRMA CLIENTE
B24: TELF. CONTACTO | C24: 992503795 | D24: PERSONA QUE RECIBE
C25: 984994680
D26: CÉDULA IDENTIDAD
B29: Acta de entrega de SIMCARDS
B30: LINEA NUEVA Y PORTABILIDAD
B31: CLIENTE | C31: =C3 -> Ismael Jahir Cruz Topanda
B32: CI/RUC | C32: =C4 -> 1725057648
B33: FECHA ACTA | C33: =C5 -> 46133
B35: DETALLE
B36: ICC | C36: NÚMERO | D36: PLAN | E36: TARIFA | F36: FECHA DE ACTIVACION
B37: =B9 -> 895930100111477706 | C37: =C9 -> PENDIENTE | D37: =D9 -> SIN LIMITE 10 | E37: =E9 -> $10.00 | F37: =F9 -> PENDIENTE
B38: =B10 -> 895930100111477707 | C38: =C10 -> PENDIENTE | D38: =D10 -> SIN LIMITE 10 | E38: =E10 -> $10.00 | F38: =F10 -> PENDIENTE
B39: =B11 -> 895930100111477705 | C39: =C11 -> PENDIENTE | D39: =D11 -> SIN LIMITE 10 | E39: =E11 -> $10.00 | F39: =F11 -> PENDIENTE
B40: =B12 -> 895930100111477671 | C40: =C12 -> PENDIENTE | D40: =D12 -> SIN LIMITE 10 | E40: =E12 -> $10.00 | F40: =F12 -> PENDIENTE
B41: =B13 -> 895930100111477678 | C41: =C13 -> PENDIENTE | D41: =D13 -> SIN LIMITE 10 | E41: =E13 -> $10.00 | F41: =F13 -> PENDIENTE
B42: =B14 -> 895930100111477714 | C42: =C14 -> PENDIENTE | D42: =D14 -> SIN LIMITE 10 | E42: =E14 -> $10.00 | F42: =F14 -> PENDIENTE
B43: =B15 -> 895930100111445438 | C43: =C15 -> 0 | D43: =D15 -> SIN LIMITE 15 | E43: =E15 -> $15.00 | F43: =F15 -> PENDIENTE
B45: • Por medio del presente Acta se deja constancia de la recepción de todos los simcards detallados, la custodia y total responsabilidad sobre los mismos de la persona que firma este documento.
B46: • Para realizar consultas, solicitudes o reclamos lo puede efectuar por medio de su asesor (a) comercial.
B49: =B21 -> GABRIEL GUZMAN
E50: FIRMA CLIENTE
B52: TELF. CONTACTO | C52: =C24 -> 992503795 | D52: PERSONA QUE RECIBE
...

Sheet Detalle
A1: ASIGANCION | B1: DETALLE
A2: LINEA NUEVA | B2: En este caso se deja la celda correspondiente al número celular en blanco, y se marca esta opción en estado
A3: PPA MOVI | B3: Aplica cuando la linea a portar se encuentra en prepago, recordar que en este caso se requiere un formato de solicitud de portabilidad por cada linea prepago
A4: POS MOVI | B4: Aplica cuando la linea a portar se encuentra bajo el mismo nombre del solicitante.
A5: CES. MOVI IND | B5: Aplica cuando la linea pertenece a un tercero que desea inluirse en la cuenta. Se requiere, CI, RUC, CESION DE DERECHOS, ULTIMA FACTURA, SP, DAS
A6: CES. MOVI EMP | B6: Aplica cuando la misma empresa migra lineas de una cuenta activa a una nueva u otra bajo su RUC. Se requiere CI, NOMBRAMIENTO, RUC. CESION DE DERECHOS, SP, DAS
A7: CES. MOVI OTRA EMP | B7: Aplica cuando una linea bajo la titularidad de otra empresa desea unirse al plan corportaivo del solicitante. Se requiere CI, NOMBRAMIENTO, RUC, CONSTITUCION Y REFORMAS, ULTIMA FACTURA, CESION DE DERECHOS, SP, DAS
A8: PPA CNT | B8: Aplica cuando la linea a portar se encuentra en prepago, recordar que en este caso se requiere un formato de solicitud de portabilidad por cada linea prepago
A9: POS CNT | B9: Aplica cuando la linea a portar se encuentra bajo el mismo nombre del solicitante.
A10: CES. CNT IND | B10: Aplica cuando la linea pertenece a un tercero que desea inluirse en la cuenta. Se requiere, CI, RUC, CESION DE DERECHOS, ULTIMA FACTURA, SP, DAS
A11: CES. CNT EMP | B11: Aplica cuando la misma empresa migra lineas de una cuenta activa a una nueva u otra bajo su RUC. Se requiere CI, NOMBRAMIENTO, RUC. CESION DE DERECHOS, SP, DAS
A12: CES. CNT OTRA EMP | B12: Aplica cuando una linea bajo la titularidad de otra empresa desea unirse al plan corportaivo del solicitante. Se requiere CI, NOMBRAMIENTO, RUC, CONSTITUCION Y REFORMAS, ULTIMA FACTURA, CESION DE DERECHOS, SP, DAS
... A19: ASIGANCION | B19: DETALLE
A20: 3 | B20: Ahora el cliente puede financiar el valor total del equipo por lo tanto es necesario especificar el tiempo que escoge el cliente, adicional está opción exime al cliente de firmar una FC, y se llena este campo siempre y cuando no se solicite payback, los equipos que estén con descuento y financiamiento en el payback si requeriran de FC. El tiempo es sin intereses.
A21: 6
A22: 9
A23: 12
A24: 15
A25: 18
A26: 24
A27: PAYBACK

Sheet ANEXO B
A5: NOMBRE DEL DA: | C5: INVERINT
A6: CÓDIGO DEL DA: | C6: 30819
A8: ANEXO “B” AL CONTRATO DE PRESTACIÓN DE SERVICIO MÓVIL AVANZADO Y SERVICIO TELEFÓNICO DE LARGA DISTANCIA INTERNACIONAL.
A9: PRIMERA: COMPARECIENTES.- Comparecen a la suscripción del presente Anexo B al contrato de prestación del
A10: servicio móvil avanzado y servicio telefónico de larga distancia internacional, en adelante el CONTRATO, por una
A11: parte la compañía: | C11: =INGRESO!B6 -> Ismael Jahir Cruz Topanda | F11: con RUC: | G11: =INGRESO!B7 -> 1725057648
A12: ,cuenta BSCS : | C12: =INGRESO!B5 -> 0
A13: EL CLIENTE y por la compañía CONSORCIO ECUATORIANO DE TELECOMUNICACIONES S.A. CONECEL,
A14: parte a la que para efectos del presente Anexo B será denominada como CONECEL.
A16: SEGUNDA: EL CLIENTE por medio del presente ANEXO B declara expresamente que ratifica los términos y
A17: condiciones del CONTRATO suscrito con CONECEL; y, que es su intención renovar | J17: adicionar
C18: las siguientes líneas al plan contratado:
A20: N° | B20: LINEA | C20: EQUIPO | D20: IMEI | E20: TARIFA BÁSICA | F20: BP VIGENTE | G20: SERVICIO ADICIONAL | I20: AUT/TAR
A21: 1 | B21: =INGRESO!#REF! -> #REF! | C21: #REF! | D21: =#REF! -> #REF! | E21: #REF! | F21: #REF! | I21: =INGRESO!#REF! -> #REF!
A22: 2 | B22: =INGRESO!B44 -> 0 | C22: #REF! | D22: =INGRESO!#REF! -> #REF! | E22: #REF! | F22: #REF! | I22: =INGRESO!I44 -> 0
A23: 3 | B23: =INGRESO!#REF! -> #REF! | C23: #REF! | D23: =INGRESO!#REF! -> #REF! | E23: #REF! | F23: #REF! | I23: =INGRESO!#REF! -> #REF!
A24: 4 | B24: =INGRESO!B45 -> 0 | C24: #REF! | D24: =INGRESO!E45 -> 0 | E24: #REF! | F24: #REF! | I24: =INGRESO!I45 -> 0
A25: 5 | B25: =INGRESO!B46 -> 0 | C25: #REF! | D25: =INGRESO!E46 -> 0 | E25: #REF! | F25: #REF! | I25: =INGRESO!I46 -> 0
A26: 6 | B26: =INGRESO!B47 -> 0 | C26: #REF! | D26: =INGRESO!E47 -> 0 | E26: #REF! | F26: #REF! | I26: =INGRESO!I47 -> 0
A27: 7 | B27: =INGRESO!B48 -> 0 | C27: #REF! | D27: =INGRESO!E48 -> 0 | E27: #REF! | F27: #REF! | I27: =INGRESO!I48
A28: 8 | B28: =INGRESO!B49 -> 0 | C28: #REF! | D28: =INGRESO!E49 -> 0 | E28: #REF! | F28: #REF! | I28: =INGRESO!I49
A29: 9 | B29: =INGRESO!B58 -> 0 | C29: #REF! | D29: =INGRESO!E58 -> 0 | E29: #REF! | F29: #REF! | I29: =INGRESO!I58
A30: 10 | B30: =INGRESO!B50 -> 0 | C30: #REF! | D30: =INGRESO!E50 -> 0 | E30: #REF! | F30: #REF! | I30: =INGRESO!I50
A31: 11 | B31: =INGRESO!B51 -> 0 | C31: #REF! | D31: =INGRESO!E51 -> 0 | E31: #REF! | F31: #REF! | I31: =INGRESO!I51
A32: 12 | B32: =INGRESO!B52 -> 0 | C32: #REF! | D32: =INGRESO!E52 -> 0 | E32: #REF! | F32: #REF! | I32: =INGRESO!I52
A33: 13 | B33: =INGRESO!B53 -> 0 | C33: #REF! | D33: =INGRESO!E53 -> 0 | E33: #REF! | F33: #REF! | I33: =INGRESO!I53
A34: 14 | B34: =INGRESO!B54 -> 0 | C34: #REF! | D34: =INGRESO!E54 -> 0 | E34: #REF! | F34: #REF! | I34: =INGRESO!I54
A35: 15 | B35: =INGRESO!B55 -> 0 | C35: #REF! | D35: =INGRESO!E55 -> 0 | E35: #REF! | F35: #REF! | I35: =INGRESO!I55
A36: 16 | B36: =INGRESO!B59 -> 0 | C36: #REF! | D36: =INGRESO!E59 -> 0 | E36: #REF! | F36: #REF! | I36: =INGRESO!I59
A37: 17 | B37: =INGRESO!B60 -> 0 | C37: #REF! | D37: =INGRESO!E60 -> 0 | E37: #REF! | F37: #REF! | I37: =INGRESO!I60
A38: 18 | B38: =INGRESO!B61 -> 0 | C38: #REF! | D38: =INGRESO!E61 -> 0 | E38: #REF! | F38: #REF! | I38: =INGRESO!I61
A39: 19 | B39: =INGRESO!B56 -> 0 | C39: #REF! | D39: =INGRESO!E56 -> 0 | E39: #REF! | F39: #REF! | I39: =INGRESO!I56
A40: 20 | B40: =INGRESO!B57 -> 0 | C40: #REF! | D40: =INGRESO!E57 -> 0 | E40: #REF! | F40: #REF! | I40: =INGRESO!I57
A41: 21 | B41: =#REF! -> #REF! | C41: #REF! | D41: =#REF! -> #REF! | E41: #REF! | F41: #REF! | I41: =#REF! -> #REF!
A42: 22 | B42: =#REF! -> #REF! | C42: #REF! | D42: =#REF! -> #REF! | E42: #REF! | F42: #REF! | I42: =#REF! -> #REF!
A43: 23 | B43: =#REF! -> #REF! | C43: #REF! | D43: =#REF! -> #REF! | E43: #REF! | F43: #REF! | I43: =#REF! -> #REF!
A44: 24 | B44: =#REF! -> #REF! | C44: #REF! | D44: =#REF! -> #REF! | E44: #REF! | F44: #REF! | I44: =#REF! -> #REF!
A45: 25 | B45: =INGRESO!B62 -> 0 | C45: #REF! | D45: =INGRESO!E62 -> 0 | E45: #REF! | F45: #REF! | I45: =INGRESO!I62
A47: TERCERA: DATOS DEL CONTACTO: Los equipos deberán ser entregados al contacto cuyos datos continuación indico:
A49: - NOMBRE: | C49: =INGRESO!B6 -> Ismael Jahir Cruz Topanda
...
